Workbook

Sheet File Index
B1: Setpoint Finance — File Index
B3: Client: NorthPeak Software · Cycle: Q1 2026 · Prepared: May 2026
B6: TAB INDEX
B7: Tab | C7: Section | D7: Purpose | E7: Audience
B8: =HYPERLINK("#Cover Page!A1","Cover Page") -> Cover Page | C8: Entry point | D8: Client-facing cover — dark, professional, three-line orientation | E8: Client
B9: =HYPERLINK("#Board Overview!A1","Board Overview") -> Board Overview | C9: Board | D9: Key metrics tile, ARR waterfall, takeaways and next steps | E9: Board / CFO
B10: =HYPERLINK("#P&L — Quarter Outlook!A1","P&L — Quarter Outlook") -> P&L — Quarter Outlook | C10: Board | D10: Current quarter P&L outlook vs budget — primary board view | E10: Board / CFO
B11: =HYPERLINK("#ARR — Quarter Outlook!A1","ARR — Quarter Outlook") -> ARR — Quarter Outlook | C11: Board | D11: Current quarter ARR outlook vs budget — primary board view | E11: Board / CFO
B12: =HYPERLINK("#P&L — Full Year!A1","P&L — Full Year") -> P&L — Full Year | C12: Board | D12: Full-year P&L forecast by quarter vs budget | E12: Board / CFO
B13: =HYPERLINK("#ARR — Full Year!A1","ARR — Full Year") -> ARR — Full Year | C13: Board | D13: Full-year ARR forecast by quarter vs budget | E13: Board / CFO
B14: =HYPERLINK("#Variance Analysis!A1","Variance Analysis") -> Variance Analysis | C14: Management | D14: What moved and why — key driver column and watchlist | E14: CFO
B15: =HYPERLINK("#P&L — QTD Results!A1","P&L — QTD Results") -> P&L — QTD Results | C15: Management | D15: Closed QTD actuals vs budget and prior year | E15: CFO
B16: =HYPERLINK("#ARR — QTD Results!A1","ARR — QTD Results") -> ARR — QTD Results | C16: Management | D16: Closed QTD ARR actuals vs budget and prior year | E16: CFO
B17: =HYPERLINK("#Natural Expense!A1","Natural Expense") -> Natural Expense | C17: Management | D17: Natural P&L by month — cost category view across 24 months | E17: CFO
B18: =HYPERLINK("#P&L Monthly!A1","P&L Monthly") -> P&L Monthly | C18: Management | D18: Functional P&L by month — historical and forecast | E18: CFO
B19: =HYPERLINK("#ARR Monthly!A1","ARR Monthly") -> ARR Monthly | C19: Management | D19: ARR rollforward by month — historical and forecast | E19: CFO
B20: =HYPERLINK("#Forecast Inputs!A1","Forecast Inputs") -> Forecast Inputs | C20: Client input | D20: Client completes this each cycle — confirm or revise assumptions | E20: Client / CFO
B21: =HYPERLINK("#Company Roster!A1","Company Roster") -> Company Roster | C21: Reference | D21: Employee-level roster — headcount and cost data | E21: CFO
B22: File Index | C22: Internal | D22: This tab — hide before sending | E22: CFO
B25: PRE-FLIGHT CHECKLIST
A26: ☐ | B26: Actuals | C26: Raw actuals integrated from GL — Revenue, COGS, OpEx, headcount
A27: ☐ | B27: ARR | C27: ARR rollforward updated — New, Expansion, Downsell, Churn actuals entered
A28: ☐ | B28: Forecast | C28: Forecast refreshed with latest assumptions from prior cycle inputs
A29: ☐ | B29: Board tabs | C29: Board Overview tiles populated — cash balance confirmed with client
A30: ☐ | B30: Commentary | C30: Draft commentary written on all Section B and C tabs
A31: ☐ | B31: Variance | C31: Variance Analysis key driver column populated — watchlist updated
A32: ☐ | B32: Inputs tab | C32: Forecast Inputs tab cleared and ready for client — trailing actuals updated
A33: ☐ | B33: Checks | C33: Model Checks tab shows all PASS — Natural EBITDA = Functional EBITDA
A34: ☐ | B34: OneDrive | C34: File saved to shared OneDrive folder — client has access confirmed
A35: ☐ | B35: File Index | C35: This tab hidden before sending — Cover Page is tab 1

Sheet Cover Page
A1: [ Logo ]
B2: FINANCE PERFORMANCE REVIEW | D2: Setpoint• Finance
B4: NorthPeak Software
B5: Board-ready view of results, outlook, and forward assumptions
B9: Q1 2026 · January — March 2026
B10: Prepared by Setpoint Finance
B11: May 2026
B13: 1. | C13: Review Sections B and C — the quarter outlook and full-year forecast.
B14: 2. | C14: Complete the Forecast Inputs tab — confirm or revise the forward assumptions.
B15: 3. | C15: We'll discuss, refine, and finalize in the monthly review meeting.
B19: Confidential Information
B20: Illustrative example prepared by Setpoint Finance to demonstrate a typical monthly deliverable. Company name and figures are fictional. | D20: Setpoint Finance
B21: Sample — Not an Actual Client

Sheet Cover Page — Print
B2: FINANCE PERFORMANCE REVIEW
B4: NorthPeak Software
B5: Board-ready view of results, outlook, and forward assumptions
B9: Q1 2026 · January — March 2026
B10: Prepared by Setpoint Finance
B11: May 2026
B14: 1. | C14: Review Sections B and C — the quarter outlook and full-year forecast.
B15: 2. | C15: Complete the Forecast Inputs tab — confirm or revise the forward assumptions.
B16: 3. | C16: We'll discuss, refine, and finalize in the monthly review meeting.
B19: Confidential Information | D19: Setpoint• Finance
B20: Illustrative example prepared by Setpoint Finance to demonstrate a typical monthly deliverable. Company name and figures are fictional.
B21: Sample — Not an Actual Client

Sheet Board Overview
B2: Board Overview
B3: ='P&L — Quarter Outlook'!A2&" · Current quarter performance vs. budget · Setpoint Finance" -> QUARTER OUTLOOK · P&L · Current quarter performance vs. budget · Setpoint Finance
B6: Ending ARR | F6: Revenue (QTD) | J6: Gross Margin % (QTD)
B7: ='ARR — Quarter Outlook'!B15*1000 -> 29640000 | F7: ='P&L — Quarter Outlook'!B9*1000 -> 6946760 | J7: ='P&L — Quarter Outlook'!B12 -> 0.82639389
B8: vs. Budget | F8: vs. Budget | J8: vs. Budget (pts)
B9: =('ARR — Quarter Outlook'!B15-'ARR — Quarter Outlook'!C15)*1000 -> -2360000 | F9: =('P&L — Quarter Outlook'!B9-'P&L — Quarter Outlook'!C9)*1000 -> -264970 | J9: =('P&L — Quarter Outlook'!B12-'P&L — Quarter Outlook'!C12)*10000 -> -11.370936
B12: NRR | F12: Cash Balance | J12: Headcount (EOP)
B13: ='ARR — Quarter Outlook'!B21 -> 1.000507 | F13: ='Forecast Inputs'!E8 -> 14200000 | J13: ='P&L — Quarter Outlook'!B25 -> 101
B14: vs. Budget (pts) | F14: =IFERROR(IF('P&L — Quarter Outlook'!B17<0,'Forecast Inputs'!E9/ABS('P&L — Quarter Outlook'!B17/3)*-1,"Cash flow positive"),"—") -> Cash flow positive | J14: vs. Budget
B15: =('ARR — Quarter Outlook'!B21-'ARR — Quarter Outlook'!C21)*10000 -> -86.77 | J15: ='P&L — Quarter Outlook'!B25-'P&L — Quarter Outlook'!C25 -> 1
B18: Key Takeaways | H18: Next Steps
B19: Q1 close: EBITDA was $29K favorable to budget overall, but March alone was $57K unfavorable, and the gap widens further into Q2. | H19: Track new-rep quota attainment monthly through Q2; this is the leading indicator for the whole variance.
B20: Revenue came in at $6.9M vs. $7.2M budget. The new AE/SDR cohort hired on schedule; bookings are the lagging variable during ramp. | H20: Confirm CS coverage normalizes as new CSM hires complete onboarding; monitor churn rate weekly.
B21: Headcount hit 100, exactly on budget for the quarter, and the hiring plan is executing as approved. | H21: No further headcount pull-forwards planned until Q1 cohort shows clear ramp progress.
B22: S&M was favorable to budget, but only because commission expense scales down with lower bookings, not independent cost discipline. | H22: Revisit FY2026 budget pacing at Q2 close if the ramp lag persists beyond plan.
B23: Trend to watch: Jan/Feb outperformed budget, March underperformed — expect further unfavorable variance into Q2 before it stabilizes.
B29: ARR Bridge ($K) | H29: Revenue & Gross Margin %
B36: Setpoint Finance · Board Overview · Prepared for management review
O41: Chart 2 — Revenue & GM%
O42: Period | P42: Actual | Q42: Budget
O43: Revenue | P43: ='P&L — Quarter Outlook'!B9 -> 6946.76 | Q43: ='P&L — Quarter Outlook'!C9 -> 7211.73
O44: GM % | P44: ='P&L — Quarter Outlook'!B12 -> 0.82639389 | Q44: ='P&L — Quarter Outlook'!C12 -> 0.82753098
O47: Chart 1 — ARR Bridge
O48: Component | P48: Actual ($K) | Q48: Budget ($K)
O49: Beginning ARR | P49: ='ARR — Quarter Outlook'!B9 -> 25000 | Q49: ='ARR — Quarter Outlook'!C9 -> 25000
O50: + New ARR | P50: ='ARR — Quarter Outlook'!B10 -> 4627.31 | Q50: ='ARR — Quarter Outlook'!C10 -> 6770.4
O51: + Expansion | P51: ='ARR — Quarter Outlook'!B11 -> 477.84 | Q51: ='ARR — Quarter Outlook'!C11 -> 574
O52: - Downsell | P52: ='ARR — Quarter Outlook'!B12 -> -134.84 | Q52: ='ARR — Quarter Outlook'!C12 -> -114.8
O53: - Gross Churn | P53: ='ARR — Quarter Outlook'!B13 -> -330.31 | Q53: ='ARR — Quarter Outlook'!C13 -> -229.6
O54: Ending ARR | P54: ='ARR — Quarter Outlook'!B15 -> 29640 | Q54: ='ARR — Quarter Outlook'!C15 -> 32000

Sheet P&L — Quarter Outlook
A2: QUARTER OUTLOOK · P&L
A3: Revenue below budget on new-hire ramp timing; costs tracking close to plan.
A4: Current-quarter outlook versus budget and prior year · All figures in $000s
B6: QTD Outlook vs Budget | F6: vs Prior Year | I6: YTD Outlook vs Budget | M6: vs Prior Year
B7: Actual | C7: Budget | D7: B/(W) | F7: Actual | G7: YoY % | I7: Actual | J7: Budget | K7: B/(W) | M7: Actual | N7: YoY %
B8: Q1 2026 | C8: Q1 2026 | D8: Q1 2026 | F8: Q1 2025 | G8: 26 vs 25 | I8: YTD 2026 | J8: YTD 2026 | K8: YTD 2026 | M8: YTD 2025 | N8: 26 vs 25
A9: Revenue | B9: 6946.76 | C9: 7211.73 | D9: =B9-C9 -> -264.97 | F9: 5062.67 | G9: =IFERROR((B9-F9)/ABS(F9),"-") -> 0.37215343 | I9: 6946.76 | J9: 7211.73 | K9: =I9-J9 -> -264.97 | M9: 5062.67 | N9: =IFERROR((I9-M9)/ABS(M9),"-") -> 0.37215343
A10: COGS | B10: 1206 | C10: 1243.8 | D10: =C10-B10 -> 37.8 | F10: 996.1 | G10: =IFERROR((B10-F10)/ABS(F10),"-") -> 0.21072182 | I10: 1206 | J10: 1243.8 | K10: =J10-I10 -> 37.8 | M10: 996.1 | N10: =IFERROR((I10-M10)/ABS(M10),"-") -> 0.21072182
A11: Gross Profit | B11: =B9-B10 -> 5740.76 | C11: =C9-C10 -> 5967.93 | D11: =B11-C11 -> -227.17 | F11: =F9-F10 -> 4066.57 | G11: =IFERROR((B11-F11)/ABS(F11),"-") -> 0.41169585 | I11: =I9-I10 -> 5740.76 | J11: =J9-J10 -> 5967.93 | K11: =I11-J11 -> -227.17 | M11: =M9-M10 -> 4066.57 | N11: =IFERROR((I11-M11)/ABS(M11),"-") -> 0.41169585
A12: Gross Margin % | B12: =IFERROR(B11/B9,0) -> 0.82639389 | C12: =IFERROR(C11/C9,0) -> 0.82753098 | D12: =IFERROR((B12-C12)*10000,0) -> -11.370936 | F12: =IFERROR(F11/F9,0) -> 0.80324611 | G12: =IFERROR((B12-F12)*10000,0) -> 231.47774 | I12: =IFERROR(I11/I9,0) -> 0.82639389 | J12: =IFERROR(J11/J9,0) -> 0.82753098 | K12: =IFERROR((I12-J12)*10000,0) -> -11.370936 | M12: =IFERROR(M11/M9,0) -> 0.80324611 | N12: =IFERROR((I12-M12)*10000,0) -> 231.47774
A13: R&D | B13: 1736.8 | C13: 1756.6 | D13: =C13-B13 -> 19.8 | F13: 1416.2 | G13: =IFERROR((B13-F13)/ABS(F13),"-") -> 0.22638045 | I13: 1736.8 | J13: 1756.6 | K13: =J13-I13 -> 19.8 | M13: 1416.2 | N13: =IFERROR((I13-M13)/ABS(M13),"-") -> 0.22638045
A14: S&M | B14: 2302.1 | C14: 2550.5 | D14: =C14-B14 -> 248.4 | F14: 1509.8 | G14: =IFERROR((B14-F14)/ABS(F14),"-") -> 0.52477149 | I14: 2302.1 | J14: 2550.5 | K14: =J14-I14 -> 248.4 | M14: 1509.8 | N14: =IFERROR((I14-M14)/ABS(M14),"-") -> 0.52477149
A15: G&A | B15: 692.9 | C15: 680.7 | D15: =C15-B15 -> -12.2 | F15: 628.7 | G15: =IFERROR((B15-F15)/ABS(F15),"-") -> 0.10211548 | I15: 692.9 | J15: 680.7 | K15: =J15-I15 -> -12.2 | M15: 628.7 | N15: =IFERROR((I15-M15)/ABS(M15),"-") -> 0.10211548
A16: Total OpEx | B16: =B13+B14+B15 -> 4731.8 | C16: =C13+C14+C15 -> 4987.8 | D16: =C16-B16 -> 256 | F16: =F13+F14+F15 -> 3554.7 | G16: =IFERROR((B16-F16)/ABS(F16),"-") -> 0.33113906 | I16: =I13+I14+I15 -> 4731.8 | J16: =J13+J14+J15 -> 4987.8 | K16: =J16-I16 -> 256 | M16: =M13+M14+M15 -> 3554.7 | N16: =IFERROR((I16-M16)/ABS(M16),"-") -> 0.33113906
A17: EBITDA | B17: =B11-B16 -> 1008.96 | C17: =C11-C16 -> 980.13 | D17: =B17-C17 -> 28.83 | F17: =F11-F16 -> 511.87 | G17: =IFERROR((B17-F17)/ABS(F17),"-") -> 0.97112548 | I17: =I11-I16 -> 1008.96 | J17: =J11-J16 -> 980.13 | K17: =I17-J17 -> 28.83 | M17: =M11-M16 -> 511.87 | N17: =IFERROR((I17-M17)/ABS(M17),"-") -> 0.97112548
A18: EBITDA Margin % | B18: =IFERROR(B17/B9,0) -> 0.14524181 | C18: =IFERROR(C17/C9,0) -> 0.13590775 | D18: =IFERROR((B18-C18)*10000,0) -> 93.340603 | F18: =IFERROR(F17/F9,0) -> 0.10110673 | G18: =IFERROR((B18-F18)*10000,0) -> 441.35082 | I18: =IFERROR(I17/I9,0) -> 0.14524181 | J18: =IFERROR(J17/J9,0) -> 0.13590775 | K18: =IFERROR((I18-J18)*10000,0) -> 93.340603 | M18: =IFERROR(M17/M9,0) -> 0.10110673 | N18: =IFERROR((I18-M18)*10000,0) -> 441.35082
A20: Headcount by Function
A21: COGS (CS, Prof Svcs, Infra) | B21: 26 | C21: 26 | D21: =C21-B21 -> 0 | F21: 22 | G21: =IFERROR((B21-F21)/ABS(F21),"-") -> 0.18181818 | I21: 26 | J21: 26 | K21: =J21-I21 -> 0 | M21: 22 | N21: =IFERROR((I21-M21)/ABS(M21),"-") -> 0.18181818
A22: R&D (Engineering, Data Science) | B22: 26 | C22: 26 | D22: =C22-B22 -> 0 | F22: 21 | G22: =IFERROR((B22-F22)/ABS(F22),"-") -> 0.23809524 | I22: 26 | J22: 26 | K22: =J22-I22 -> 0 | M22: 21 | N22: =IFERROR((I22-M22)/ABS(M22),"-") -> 0.23809524
A23: S&M (Sales, Marketing) | B23: 35 | C23: 35 | D23: =C23-B23 -> 0 | F23: 27 | G23: =IFERROR((B23-F23)/ABS(F23),"-") -> 0.2962963 | I23: 35 | J23: 35 | K23: =J23-I23 -> 0 | M23: 27 | N23: =IFERROR((I23-M23)/ABS(M23),"-") -> 0.2962963
A24: G&A (Finance, People) | B24: 14 | C24: 13 | D24: =C24-B24 -> -1 | F24: 12 | G24: =IFERROR((B24-F24)/ABS(F24),"-") -> 0.16666667 | I24: 14 | J24: 13 | K24: =J24-I24 -> -1 | M24: 12 | N24: =IFERROR((I24-M24)/ABS(M24),"-") -> 0.16666667
A25: Total Headcount | B25: =B21+B22+B23+B24 -> 101 | C25: =C21+C22+C23+C24 -> 100 | D25: =C25-B25 -> -1 | F25: =F21+F22+F23+F24 -> 82 | G25: =IFERROR((B25-F25)/ABS(F25),"-") -> 0.23170732 | I25: =I21+I22+I23+I24 -> 101 | J25: =J21+J22+J23+J24 -> 100 | K25: =J25-I25 -> -1 | M25: =M21+M22+M23+M24 -> 82 | N25: =IFERROR((I25-M25)/ABS(M25),"-") -> 0.23170732
A27: COMMENTARY
A28: — EBITDA $29K favorable to budget for the quarter as a whole — but March alone was already $57K unfavorable; the in-quarter trend, not the QTD total, is the signal to watch.
A29: — Revenue $6.9M, $265K below budget — Q1 AE/SDR cohort hired on schedule; new ARR bookings are the lagging variable during ramp.
A30: — COGS $38K unfavorable — payment processing fees scale with revenue; hosting in line with plan.
A31: — S&M $248K favorable — commission expense scales with actual bookings, not headcount; same headcount as budget, lower payout on lower bookings.
A32: — G&A $12K unfavorable — Finance/HR hiring modestly ahead of plan, largely offset by lower recruiting spend.
A34: All figures in $000s · Q1 2026 outlook = actuals through March 2026 · Budget = approved FY2026 plan

Sheet ARR — Quarter Outlook
A2: QUARTER OUTLOOK · ARR
A3: ARR growth below budget on new-rep ramp timing; retention pressure from stretched CS capacity.
A4: Current-quarter ARR outlook versus budget and prior year · All figures in $000s
B6: QTD Outlook vs Budget | F6: vs Prior Year | I6: YTD Outlook vs Budget | M6: vs Prior Year
B7: Actual | C7: Budget | D7: B/(W) | F7: Actual | G7: YoY % | I7: Actual | J7: Budget | K7: B/(W) | M7: Actual | N7: YoY %
B8: Q1 2026 | C8: Q1 2026 | D8: Q1 2026 | F8: Q1 2025 | G8: 26 vs 25 | I8: YTD 2026 | J8: YTD 2026 | K8: YTD 2026 | M8: YTD 2025 | N8: 26 vs 25
A9: Beginning ARR | B9: 25000 | C9: 25000 | D9: =B9-C9 -> 0 | F9: 19077 | G9: =IFERROR((B9-F9)/ABS(F9),"-") -> 0.31047859 | I9: 25000 | J9: 25000 | K9: =I9-J9 -> 0 | M9: 19077 | N9: =IFERROR((I9-M9)/ABS(M9),"-") -> 0.31047859
A10: + New ARR | B10: 4627.31 | C10: 6770.4 | D10: =B10-C10 -> -2143.09 | F10: 1541.91 | G10: =IFERROR((B10-F10)/ABS(F10),"-") -> 2.0010247 | I10: 4627.31 | J10: 6770.4 | K10: =I10-J10 -> -2143.09 | M10: 1541.91 | N10: =IFERROR((I10-M10)/ABS(M10),"-") -> 2.0010247
A11: + Expansion ARR | B11: 477.84 | C11: 574 | D11: =B11-C11 -> -96.16 | F11: 353.05 | G11: =IFERROR((B11-F11)/ABS(F11),"-") -> 0.35346268 | I11: 477.84 | J11: 574 | K11: =I11-J11 -> -96.16 | M11: 353.05 | N11: =IFERROR((I11-M11)/ABS(M11),"-") -> 0.35346268
A12: − Downsell ARR | B12: -134.84 | C12: -114.8 | D12: =C12-B12 -> 20.04 | F12: -94.58 | G12: =IFERROR((B12-F12)/ABS(F12),"-") -> -0.42567139 | I12: -134.84 | J12: -114.8 | K12: =J12-I12 -> 20.04 | M12: -94.58 | N12: =IFERROR((I12-M12)/ABS(M12),"-") -> -0.42567139
A13: − Gross Churn ARR | B13: -330.31 | C13: -229.6 | D13: =C13-B13 -> 100.71 | F13: -189.38 | G13: =IFERROR((B13-F13)/ABS(F13),"-") -> -0.74416517 | I13: -330.31 | J13: -229.6 | K13: =J13-I13 -> 100.71 | M13: -189.38 | N13: =IFERROR((I13-M13)/ABS(M13),"-") -> -0.74416517
A14: Net New ARR | B14: =B10+B11+B12+B13 -> 4640 | C14: =C10+C11+C12+C13 -> 7000 | D14: =B14-C14 -> -2360 | F14: =F10+F11+F12+F13 -> 1611 | G14: =IFERROR((B14-F14)/ABS(F14),"-") -> 1.8801986 | I14: =I10+I11+I12+I13 -> 4640 | J14: =J10+J11+J12+J13 -> 7000 | K14: =I14-J14 -> -2360 | M14: =M10+M11+M12+M13 -> 1611 | N14: =IFERROR((I14-M14)/ABS(M14),"-") -> 1.8801986
A15: Ending ARR | B15: =B9+B10+B11+B12+B13 -> 29640 | C15: =C9+C10+C11+C12+C13 -> 32000 | D15: =B15-C15 -> -2360 | F15: =F9+F10+F11+F12+F13 -> 20688 | G15: =IFERROR((B15-F15)/ABS(F15),"-") -> 0.43271462 | I15: =I9+I10+I11+I12+I13 -> 29640 | J15: =J9+J10+J11+J12+J13 -> 32000 | K15: =I15-J15 -> -2360 | M15: =M9+M10+M11+M12+M13 -> 20688 | N15: =IFERROR((I15-M15)/ABS(M15),"-") -> 0.43271462
A17: SAAS KPIS
A18: ARR Churn Rate | B18: 0.018606 | C18: 0.013776 | D18: =IFERROR((B18-C18)*10000*-1,0) -> -48.3 | F18: 0.014885 | G18: =IFERROR((B18-F18)*10000*-1,0) -> -37.21 | I18: 0.018606 | J18: 0.013776 | K18: =IFERROR((I18-J18)*10000*-1,0) -> -48.3 | M18: 0.014885 | N18: =IFERROR((I18-M18)*10000*-1,0) -> -37.21
A19: Expansion Rate | B19: 0.019114 | C19: 0.02296 | D19: =IFERROR((B19-C19)*10000*1,0) -> -38.46 | F19: 0.018507 | G19: =IFERROR((B19-F19)*10000*1,0) -> 6.07 | I19: 0.019114 | J19: 0.02296 | K19: =IFERROR((I19-J19)*10000*1,0) -> -38.46 | M19: 0.018507 | N19: =IFERROR((I19-M19)*10000*1,0) -> 6.07
A20: Gross Revenue Retention (GRR) | B20: 0.981394 | C20: 0.986224 | D20: =IFERROR((B20-C20)*10000*1,0) -> -48.3 | F20: 0.985115 | G20: =IFERROR((B20-F20)*10000*1,0) -> -37.21 | I20: 0.981394 | J20: 0.986224 | K20: =IFERROR((I20-J20)*10000*1,0) -> -48.3 | M20: 0.985115 | N20: =IFERROR((I20-M20)*10000*1,0) -> -37.21
A21: Net Revenue Retention (NRR) | B21: 1.000507 | C21: 1.009184 | D21: =IFERROR((B21-C21)*10000*1,0) -> -86.77 | F21: 1.003622 | G21: =IFERROR((B21-F21)*10000*1,0) -> -31.15 | I21: 1.000507 | J21: 1.009184 | K21: =IFERROR((I21-J21)*10000*1,0) -> -86.77 | M21: 1.003622 | N21: =IFERROR((I21-M21)*10000*1,0) -> -31.15
A22: Net New ARR as % of Beg ARR | B22: =IFERROR(B14/B9,0) -> 0.1856 | C22: =IFERROR(C14/C9,0) -> 0.28 | D22: =IFERROR((B22-C22)*10000,0) -> -944 | F22: =IFERROR(F14/F9,0) -> 0.08444724 | G22: =IFERROR((B22-F22)*10000,0) -> 1011.5276 | I22: =IFERROR(I14/I9,0) -> 0.1856 | J22: =IFERROR(J14/J9,0) -> 0.28 | K22: =IFERROR((I22-J22)*10000,0) -> -944 | M22: =IFERROR(M14/M9,0) -> 0.08444724 | N22: =IFERROR((I22-M22)*10000,0) -> 1011.5276
A24: COMMENTARY
A25: — Ending ARR $29.6M, ~$2.4M below budget — new ARR bookings lag plan while the Q1 AE cohort ramps to full productivity.
A26: — New ARR $4.6M, below the $6.8M budget — reps are hired and onboarded on schedule; output is the lagging variable, not headcount.
A27: — Expansion ARR roughly in line with plan — existing-customer upsell motion unaffected by the new-hire ramp.
A28: — GRR below budget — CS capacity stretched during the hiring ramp; new CSM hires now onboarding to rebuild coverage.
A29: — NRR below budget for the same reason; expect normalization as new CS hires reach full capacity in Q2.
A31: All figures in $000s · Q1 2026 outlook = actuals through March 2026 · Budget = approved FY2026 plan

Sheet P&L — Full Year
A2: FULL-YEAR FORECAST · P&L
A3: Full-year P&L: Q1 actual, Q2–Q4 forecast (from validated model) vs. approved FY2026 budget.
A4: Full-year P&L forecast versus budget · Quarterly cadence · All figures in $000s
B6: Forecast | H6: vs Full-Year Budget
B7: Q1 Actual | C7: Q2 | D7: Q3 | E7: Q4 | F7: FY Forecast | H7: FY Budget | I7: B/(W) $ | J7: B/(W) %
B8: 2026 | C8: 2026 | D8: 2026 | E8: 2026 | F8: 2026 | H8: 2026 | I8: FY 2026 | J8: FY 2026
A9: Revenue | B9: 6946.8 | C9: 8469.8 | D9: 10398.9 | E9: 12339.6 | F9: =B9+C9+D9+E9 -> 38155.1 | H9: 40929.8 | I9: =F9-H9 -> -2774.7 | J9: =IFERROR((F9-H9)/ABS(H9),"-") -> -0.067791682
A10: COGS | B10: 1206 | C10: 1720.6 | D10: 1920.3 | E10: 2078.6 | F10: =B10+C10+D10+E10 -> 6925.5 | H10: 5927.9 | I10: =F10-H10 -> 997.6 | J10: =IFERROR((F10-H10)/ABS(H10),"-") -> 0.16828894
A11: Gross Profit | B11: =B9-B10 -> 5740.8 | C11: =C9-C10 -> 6749.2 | D11: =D9-D10 -> 8478.6 | E11: =E9-E10 -> 10261 | F11: =F9-F10 -> 31229.6 | H11: =H9-H10 -> 35001.9 | I11: =F11-H11 -> -3772.3 | J11: =IFERROR((F11-H11)/ABS(H11),"-") -> -0.10777415
A12: Gross Margin % | B12: =B11/B9 -> 0.82639489 | C12: =C11/C9 -> 0.79685471 | D12: =D11/D9 -> 0.81533624 | E12: =E11/E9 -> 0.83155046 | F12: =F11/F9 -> 0.81849084 | H12: =H11/H9 -> 0.85516909 | I12: =(F12-H12)*10000 -> -366.7825
A13: R&D | B13: 1736.8 | C13: 1995 | D13: 2288.9 | E13: 2516.1 | F13: =B13+C13+D13+E13 -> 8536.8 | H13: 8770.9 | I13: =F13-H13 -> -234.1 | J13: =IFERROR((F13-H13)/ABS(H13),"-") -> -0.026690533
A14: S&M | B14: 2302.1 | C14: 4182.4 | D14: 4925.8 | E14: 5522.2 | F14: =B14+C14+D14+E14 -> 16932.5 | H14: 13169.2 | I14: =F14-H14 -> 3763.3 | J14: =IFERROR((F14-H14)/ABS(H14),"-") -> 0.28576527
A15: G&A | B15: 692.9 | C15: 596.2 | D15: 633.8 | E15: 663.4 | F15: =B15+C15+D15+E15 -> 2586.3 | H15: 3172 | I15: =F15-H15 -> -585.7 | J15: =IFERROR((F15-H15)/ABS(H15),"-") -> -0.18464691
A16: Total OpEx | B16: =SUM(B13:B15) -> 4731.8 | C16: =SUM(C13:C15) -> 6773.6 | D16: =SUM(D13:D15) -> 7848.5 | E16: =SUM(E13:E15) -> 8701.7 | F16: =SUM(F13:F15) -> 28055.6 | H16: =SUM(H13:H15) -> 25112.1 | I16: =F16-H16 -> 2943.5 | J16: =IFERROR((F16-H16)/ABS(H16),"-") -> 0.11721441
A17: EBITDA | B17: =B11-B16 -> 1009 | C17: =C11-C16 -> -24.4 | D17: =D11-D16 -> 630.1 | E17: =E11-E16 -> 1559.3 | F17: =F11-F16 -> 3174 | H17: =H11-H16 -> 9889.8 | I17: =F17-H17 -> -6715.8 | J17: =IFERROR((F17-H17)/ABS(H17),"-") -> -0.67906328
A18: EBITDA Margin % | B18: =B17/B9 -> 0.14524673 | C18: =C17/C9 -> -0.0028808236 | D18: =D17/D9 -> 0.060592947 | E18: =E17/E9 -> 0.12636552 | F18: =F17/F9 -> 0.083186782 | H18: =H17/H9 -> 0.24162835 | I18: =(F18-H18)*10000 -> -1584.4157
A21: Headcount by Function
A22: COGS (CS, Prof Svcs, Infra) | B22: 26 | C22: 30 | D22: 32 | E22: 34 | F22: =E22 -> 34 | H22: 34 | I22: =F22-H22 -> 0
A23: R&D (Engineering, Data Science) | B23: 26 | C23: 32 | D23: 36 | E23: 39 | F23: =E23 -> 39 | H23: 39 | I23: =F23-H23 -> 0
A24: S&M (Sales, Marketing) | B24: 35 | C24: 49 | D24: 57 | E24: 63 | F24: =E24 -> 63 | H24: 58 | I24: =F24-H24 -> 5
A25: G&A (Finance, People) | B25: 14 | C25: 15 | D25: 16 | E25: 17 | F25: =E25 -> 17 | H25: 17 | I25: =F25-H25 -> 0
A26: Total Headcount | B26: =SUM(B22:B25) -> 101 | C26: =SUM(C22:C25) -> 126 | D26: =SUM(D22:D25) -> 141 | E26: =SUM(E22:E25) -> 153 | F26: =E26 -> 153 | H26: =SUM(H22:H25) -> 148 | I26: =F26-H26 -> 5

Sheet ARR — Full Year
A2: FULL-YEAR FORECAST · ARR
A3: Full-year forecast: Q1 actual, Q2–Q4 outlook, versus full-year budget.
A4: Full-year ARR forecast versus budget · Quarterly cadence · All figures in $000s
B6: Forecast | H6: vs Full-Year Budget
B7: Q1 Actual | C7: Q2 | D7: Q3 | E7: Q4 | F7: FY Forecast | H7: FY Budget | I7: B/(W) $ | J7: B/(W) %
B8: 2026 | C8: 2026 | D8: 2026 | E8: 2026 | F8: 2026 | H8: 2026 | I8: FY 2026 | J8: FY 2026
A9: Beginning ARR | B9: 25000 | C9: 29640 | D9: 37333.2 | E9: 45072.7 | F9: =B9 -> 25000 | H9: 25000 | I9: =F9-H9 -> 0 | J9: =IFERROR((F9-H9)/ABS(H9),"-") -> 0
A10: + New ARR | B10: 4627.3 | C10: 7500 | D10: 7500 | E10: 7500 | F10: =B10+C10+D10+E10 -> 27127.3 | H10: 31685.4 | I10: =F10-H10 -> -4558.1 | J10: =IFERROR((F10-H10)/ABS(H10),"-") -> -0.1438549
A11: + Expansion ARR | B11: 477.8 | C11: 676.2 | D11: 838.1 | E11: 1001 | F11: =B11+C11+D11+E11 -> 2993.1 | H11: 3286.5 | I11: =F11-H11 -> -293.4 | J11: =IFERROR((F11-H11)/ABS(H11),"-") -> -0.089274304
A12: − Downsell ARR | B12: -134.8 | C12: -144.9 | D12: -179.6 | E12: -214.5 | F12: =B12+C12+D12+E12 -> -673.8 | H12: -657.3 | I12: =F12-H12 -> -16.5 | J12: =IFERROR((F12-H12)/ABS(H12),"-") -> -0.025102693
A13: − Gross Churn ARR | B13: -330.3 | C13: -338.1 | D13: -419.1 | E13: -500.5 | F13: =B13+C13+D13+E13 -> -1588 | H13: -1314.6 | I13: =F13-H13 -> -273.4 | J13: =IFERROR((F13-H13)/ABS(H13),"-") -> -0.20797201
A14: Net New ARR | B14: =SUM(B10:B13) -> 4640 | C14: =SUM(C10:C13) -> 7693.2 | D14: =SUM(D10:D13) -> 7739.4 | E14: =SUM(E10:E13) -> 7786 | F14: =B14+C14+D14+E14 -> 27858.6 | H14: =SUM(H10:H13) -> 33000 | I14: =F14-H14 -> -5141.4 | J14: =IFERROR((F14-H14)/ABS(H14),"-") -> -0.1558
A15: Ending ARR | B15: =B9+B14 -> 29640 | C15: =C9+C14 -> 37333.2 | D15: =D9+D14 -> 45072.6 | E15: =E9+E14 -> 52858.7 | F15: =E15 -> 52858.7 | H15: =H9+H14 -> 58000 | I15: =F15-H15 -> -5141.3 | J15: =IFERROR((F15-H15)/ABS(H15),"-") -> -0.088643103
A17: SAAS KPIS
A18: ARR Churn Rate | F18: =-(F12+F13)/F9 -> 0.090472 | H18: =-(H12+H13)/H9 -> 0.078876 | I18: =(F18-H18)*10000 -> 115.96 | J18: -
A19: Expansion Rate | F19: =F11/F9 -> 0.119724 | H19: =H11/H9 -> 0.13146 | I19: =(F19-H19)*10000 -> -117.36 | J19: -
A20: Gross Revenue Retention (GRR) | F20: =(F9+F12+F13)/F9 -> 0.909528 | H20: =(H9+H12+H13)/H9 -> 0.921124 | I20: =(F20-H20)*10000 -> -115.96 | J20: -
A21: Net Revenue Retention (NRR) | F21: =(F9+F11+F12+F13)/F9 -> 1.029252 | H21: =(H9+H11+H12+H13)/H9 -> 1.052584 | I21: =(F21-H21)*10000 -> -233.32 | J21: -
A22: Net New ARR as % of Beg ARR | F22: =F14/F9 -> 1.114344 | H22: =H14/H9 -> 1.32 | I22: =(F22-H22)*10000 -> -2056.56 | J22: -

Sheet Variance Analysis
A2: VARIANCE ANALYSIS · MANAGEMENT USE ONLY
A3: What moved, by how much, and why.
A4: Q1 2026 actual versus budget · Functional P&L · All figures in $000s · Not for board distribution
B6: Q1 2026 — Actual vs Budget | G6: Key Driver
B7: Actual | C7: Budget | D7: B/(W) $ | E7: B/(W) % | G7: Material variances only — add context here
A8: Functional P&L | B8: Q1 2026 | C8: Q1 2026 | D8: Q1 2026 | E8: Q1 2026
A9: Revenue | B9: 6946.76 | C9: 7211.73 | D9: =B9-C9 -> -264.97 | E9: =IFERROR((B9-C9)/ABS(C9),0) -> -0.036741531 | G9: Revenue $6.95M vs. $7.21M budget — Q1 AE/SDR cohort hired on schedule; new ARR bookings ($4.6M vs. $6.8M budget) are the lagging variable as reps ramp to quota.
A10: COGS | B10: 1206 | C10: 1243.8 | D10: =C10-B10 -> 37.8 | E10: =IFERROR((C10-B10)/ABS(C10),0) -> 0.030390738 | G10: COGS $38K unfavorable — payment processing fees scale with revenue as expected; hosting in line with plan.
A11: Gross Profit | B11: =B9-B10 -> 5740.76 | C11: =C9-C10 -> 5967.93 | D11: =B11-C11 -> -227.17 | E11: =IFERROR((B11-C11)/ABS(C11),0) -> -0.038065125 | G11: Gross profit $119K below budget — the revenue shortfall is only partially offset by lower COGS; margin rate is not the issue.
A12: Gross Margin % | B12: =IFERROR(B11/B9,0) -> 0.82639389 | C12: =IFERROR(C11/C9,0) -> 0.82753098 | D12: =IFERROR((B12-C12)*10000,0) -> -11.370936 | E12: =IFERROR((B12-C12)*10000,0) -> -11.370936 | G12: GM% modestly favorable to budget — cost discipline in COGS, not mix, is driving the small margin outperformance.
A13: R&D | B13: 1736.8 | C13: 1756.6 | D13: =C13-B13 -> 19.8 | E13: =IFERROR((C13-B13)/ABS(C13),0) -> 0.011271775 | G13: R&D $20K favorable — engineering and data science hiring tracking to plan.
A14: S&M | B14: 2302.1 | C14: 2550.5 | D14: =C14-B14 -> 248.4 | E14: =IFERROR((C14-B14)/ABS(C14),0) -> 0.097392668 | G14: S&M $248K favorable — same headcount as budget, but commission expense scales with actual bookings; lower bookings mean lower payout, not independent cost discipline.
A15: G&A | B15: 692.9 | C15: 680.7 | D15: =C15-B15 -> -12.2 | E15: =IFERROR((C15-B15)/ABS(C15),0) -> -0.017922727 | G15: G&A $12K unfavorable — Finance/HR hiring modestly ahead of plan; largely offset by lower recruiting spend.
A16: Total OpEx | B16: =B13+B14+B15 -> 4731.8 | C16: =C13+C14+C15 -> 4987.8 | D16: =C16-B16 -> 256 | E16: =IFERROR((C16-B16)/ABS(C16),0) -> 0.051325234 | G16: Total OpEx $168K favorable overall — driven almost entirely by the commission self-correction in S&M, not broad cost control.
A17: EBITDA | B17: =B11-B16 -> 1008.96 | C17: =C11-C16 -> 980.13 | D17: =B17-C17 -> 28.83 | E17: =IFERROR((B17-C17)/ABS(C17),0) -> 0.029414465 | G17: EBITDA $29K favorable to budget for the quarter — but this nets a strong Jan/Feb against a March that already turned unfavorable; the trend, not the QTD total, is the signal.
A18: EBITDA Margin % | B18: =IFERROR(B17/B9,0) -> 0.14524181 | C18: =IFERROR(C17/C9,0) -> 0.13590775 | D18: =IFERROR((B18-C18)*10000,0) -> 93.340603 | E18: =IFERROR((B18-C18)*10000,0) -> 93.340603 | G18: Margin rate favorable on a blended QTD basis; watch the monthly trend, not the average, heading into Q2.
A21: Headcount by Function
A22: COGS (CS, Prof Svcs, Infra) | B22: 26 | C22: 26 | D22: =C22-B22 -> 0 | E22: =IFERROR((C22-B22)/ABS(C22),0) -> 0
A23: R&D (Engineering, Data Science) | B23: 26 | C23: 26 | D23: =C23-B23 -> 0 | E23: =IFERROR((C23-B23)/ABS(C23),0) -> 0 | G23: One additional engineering hire vs. budget — pulled forward to support the new product investment.
A24: S&M (Sales, Marketing) | B24: 35 | C24: 35 | D24: =C24-B24 -> 0 | E24: =IFERROR((C24-B24)/ABS(C24),0) -> 0 | G24: Sales headcount on budget for the quarter — the AE/SDR cohort arrived on schedule; the gap is in their ramp, not their start dates.
A25: G&A (Finance, People) | B25: 14 | C25: 13 | D25: =C25-B25 -> -1 | E25: =IFERROR((C25-B25)/ABS(C25),0) -> -0.076923077 | G25: Finance/HR added slightly ahead of plan to support the scaled hiring process itself.
A26: Total Headcount | B26: =SUM(B22:B25) -> 101 | C26: =SUM(C22:C25) -> 100 | D26: =C26-B26 -> -1 | E26: =IFERROR((C26-B26)/ABS(C26),0) -> -0.01 | G26: Total headcount finished 1 over budget for the quarter (101 vs. 100) — the G&A build-out ran slightly ahead of plan; the revenue gap is in new-rep productivity, not headcount.
A28: WATCHLIST
A29: Item | B29: Metric / Area | D29: Status | E29: Owner | G29: Next Action
A30: 1 | B30: New AE cohort ramp — 12 reps hired Q1, not yet at full quota | D30: On track | E30: VP Sales | G30: Track monthly quota attainment by cohort; confirm ramp curve holds through Q2.
A31: 2 | B31: ARR churn — elevated in Q1 vs. budget (CS capacity stretched) | D31: Monitoring | E31: VP Customer Success | G31: New CSM hires now onboarding; confirm churn rate normalizes by Q2 close.
A32: 3 | B32: Engineering headcount — 1 hire ahead of plan | D32: Tracking | E32: VP Engineering | G32: Confirm product roadmap justifies the pulled-forward hire; no further pull-forwards planned.
A33: 4 | B33: S&M cost run-rate ahead of bookings | D33: Expected — timing | E33: CFO | G33: Reassess if bookings haven't inflected by Q2 close; this is the key metric to watch.
A35: Management use only · Not for board distribution · Prepared by Setpoint Finance · Q1 2026

Sheet P&L — QTD Results
A2: QTD ACTUALS · P&L
A3: Revenue below budget on new-hire ramp timing; costs tracking close to plan.
A4: Q1 2026 actual results versus budget and prior year · All figures in $000s
B6: QTD Outlook vs Budget | F6: vs Prior Year | I6: YTD Outlook vs Budget | M6: vs Prior Year
B7: Actual | C7: Budget | D7: B/(W) | F7: Actual | G7: YoY % | I7: Actual | J7: Budget | K7: B/(W) | M7: Actual | N7: YoY %
B8: Q1 2026 | C8: Q1 2026 | D8: Q1 2026 | F8: Q1 2025 | G8: 26 vs 25 | I8: YTD 2026 | J8: YTD 2026 | K8: YTD 2026 | M8: YTD 2025 | N8: 26 vs 25
A9: Revenue | B9: 6946.76 | C9: 7211.73 | D9: =B9-C9 -> -264.97 | F9: 5062.67 | G9: =IFERROR((B9-F9)/ABS(F9),"-") -> 0.37215343 | I9: 6946.76 | J9: 7211.73 | K9: =I9-J9 -> -264.97 | M9: 5062.67 | N9: =IFERROR((I9-M9)/ABS(M9),"-") -> 0.37215343
A10: COGS | B10: 1206 | C10: 1243.8 | D10: =C10-B10 -> 37.8 | F10: 996.1 | G10: =IFERROR((B10-F10)/ABS(F10),"-") -> 0.21072182 | I10: 1206 | J10: 1243.8 | K10: =J10-I10 -> 37.8 | M10: 996.1 | N10: =IFERROR((I10-M10)/ABS(M10),"-") -> 0.21072182
A11: Gross Profit | B11: =B9-B10 -> 5740.76 | C11: =C9-C10 -> 5967.93 | D11: =B11-C11 -> -227.17 | F11: =F9-F10 -> 4066.57 | G11: =IFERROR((B11-F11)/ABS(F11),"-") -> 0.41169585 | I11: =I9-I10 -> 5740.76 | J11: =J9-J10 -> 5967.93 | K11: =I11-J11 -> -227.17 | M11: =M9-M10 -> 4066.57 | N11: =IFERROR((I11-M11)/ABS(M11),"-") -> 0.41169585
A12: Gross Margin % | B12: =IFERROR(B11/B9,0) -> 0.82639389 | C12: =IFERROR(C11/C9,0) -> 0.82753098 | D12: =IFERROR((B12-C12)*10000,0) -> -11.370936 | F12: =IFERROR(F11/F9,0) -> 0.80324611 | G12: =IFERROR((B12-F12)*10000,0) -> 231.47774 | I12: =IFERROR(I11/I9,0) -> 0.82639389 | J12: =IFERROR(J11/J9,0) -> 0.82753098 | K12: =IFERROR((I12-J12)*10000,0) -> -11.370936 | M12: =IFERROR(M11/M9,0) -> 0.80324611 | N12: =IFERROR((I12-M12)*10000,0) -> 231.47774
A13: R&D | B13: 1736.8 | C13: 1756.6 | D13: =C13-B13 -> 19.8 | F13: 1416.2 | G13: =IFERROR((B13-F13)/ABS(F13),"-") -> 0.22638045 | I13: 1736.8 | J13: 1756.6 | K13: =J13-I13 -> 19.8 | M13: 1416.2 | N13: =IFERROR((I13-M13)/ABS(M13),"-") -> 0.22638045
A14: S&M | B14: 2302.1 | C14: 2550.5 | D14: =C14-B14 -> 248.4 | F14: 1509.8 | G14: =IFERROR((B14-F14)/ABS(F14),"-") -> 0.52477149 | I14: 2302.1 | J14: 2550.5 | K14: =J14-I14 -> 248.4 | M14: 1509.8 | N14: =IFERROR((I14-M14)/ABS(M14),"-") -> 0.52477149
A15: G&A | B15: 692.9 | C15: 680.7 | D15: =C15-B15 -> -12.2 | F15: 628.7 | G15: =IFERROR((B15-F15)/ABS(F15),"-") -> 0.10211548 | I15: 692.9 | J15: 680.7 | K15: =J15-I15 -> -12.2 | M15: 628.7 | N15: =IFERROR((I15-M15)/ABS(M15),"-") -> 0.10211548
A16: Total OpEx | B16: =B13+B14+B15 -> 4731.8 | C16: =C13+C14+C15 -> 4987.8 | D16: =C16-B16 -> 256 | F16: =F13+F14+F15 -> 3554.7 | G16: =IFERROR((B16-F16)/ABS(F16),"-") -> 0.33113906 | I16: =I13+I14+I15 -> 4731.8 | J16: =J13+J14+J15 -> 4987.8 | K16: =J16-I16 -> 256 | M16: =M13+M14+M15 -> 3554.7 | N16: =IFERROR((I16-M16)/ABS(M16),"-") -> 0.33113906
A17: EBITDA | B17: =B11-B16 -> 1008.96 | C17: =C11-C16 -> 980.13 | D17: =B17-C17 -> 28.83 | F17: =F11-F16 -> 511.87 | G17: =IFERROR((B17-F17)/ABS(F17),"-") -> 0.97112548 | I17: =I11-I16 -> 1008.96 | J17: =J11-J16 -> 980.13 | K17: =I17-J17 -> 28.83 | M17: =M11-M16 -> 511.87 | N17: =IFERROR((I17-M17)/ABS(M17),"-") -> 0.97112548
A18: EBITDA Margin % | B18: =IFERROR(B17/B9,0) -> 0.14524181 | C18: =IFERROR(C17/C9,0) -> 0.13590775 | D18: =IFERROR((B18-C18)*10000,0) -> 93.340603 | F18: =IFERROR(F17/F9,0) -> 0.10110673 | G18: =IFERROR((B18-F18)*10000,0) -> 441.35082 | I18: =IFERROR(I17/I9,0) -> 0.14524181 | J18: =IFERROR(J17/J9,0) -> 0.13590775 | K18: =IFERROR((I18-J18)*10000,0) -> 93.340603 | M18: =IFERROR(M17/M9,0) -> 0.10110673 | N18: =IFERROR((I18-M18)*10000,0) -> 441.35082
A21: Headcount by Function
A22: COGS (CS, Prof Svcs, Infra) | B22: 26 | C22: 26 | D22: =C22-B22 -> 0 | F22: 22 | G22: =IFERROR((B22-F22)/ABS(F22),"-") -> 0.18181818 | I22: 26 | J22: 26 | K22: =J22-I22 -> 0 | M22: 22 | N22: =IFERROR((I22-M22)/ABS(M22),"-") -> 0.18181818
A23: R&D (Engineering, Data Science) | B23: 26 | C23: 26 | D23: =C23-B23 -> 0 | F23: 21 | G23: =IFERROR((B23-F23)/ABS(F23),"-") -> 0.23809524 | I23: 26 | J23: 26 | K23: =J23-I23 -> 0 | M23: 21 | N23: =IFERROR((I23-M23)/ABS(M23),"-") -> 0.23809524
A24: S&M (Sales, Marketing) | B24: 35 | C24: 35 | D24: =C24-B24 -> 0 | F24: 27 | G24: =IFERROR((B24-F24)/ABS(F24),"-") -> 0.2962963 | I24: 35 | J24: 35 | K24: =J24-I24 -> 0 | M24: 27 | N24: =IFERROR((I24-M24)/ABS(M24),"-") -> 0.2962963
A25: G&A (Finance, People) | B25: 14 | C25: 13 | D25: =C25-B25 -> -1 | F25: 12 | G25: =IFERROR((B25-F25)/ABS(F25),"-") -> 0.16666667 | I25: 14 | J25: 13 | K25: =J25-I25 -> -1 | M25: 12 | N25: =IFERROR((I25-M25)/ABS(M25),"-") -> 0.16666667
A26: Total Headcount | B26: =B22+B23+B24+B25 -> 101 | C26: =C22+C23+C24+C25 -> 100 | D26: =C26-B26 -> -1 | F26: =F22+F23+F24+F25 -> 82 | G26: =IFERROR((B26-F26)/ABS(F26),"-") -> 0.23170732 | I26: =I22+I23+I24+I25 -> 101 | J26: =J22+J23+J24+J25 -> 100 | K26: =J26-I26 -> -1 | M26: =M22+M23+M24+M25 -> 82 | N26: =IFERROR((I26-M26)/ABS(M26),"-") -> 0.23170732
A28: COMMENTARY
A29: — EBITDA $29K favorable to budget for the quarter as a whole — but March alone was already $57K unfavorable; the in-quarter trend, not the QTD total, is the signal to watch.
A30: — Revenue $6.9M, $265K below budget — Q1 AE/SDR cohort hired on schedule; new ARR bookings are the lagging variable during ramp.
A31: — COGS $38K unfavorable — payment processing fees scale with revenue; hosting in line with plan.
A32: — S&M $248K favorable — commission expense scales with actual bookings, not headcount; same headcount as budget, lower payout on lower bookings.
A33: — G&A $12K unfavorable — Finance/HR hiring modestly ahead of plan, largely offset by lower recruiting spend.
A35: All figures in $000s · Actuals through March 2026 · Budget = approved FY2026 plan

Sheet ARR — QTD Results
A2: QTD ACTUALS · ARR
A3: ARR growth below budget on new-rep ramp timing; retention pressure from stretched CS capacity.
A4: Q1 2026 actual ARR results versus budget and prior year · All figures in $000s
B6: QTD Outlook vs Budget | F6: vs Prior Year | I6: YTD Outlook vs Budget | M6: vs Prior Year
B7: Actual | C7: Budget | D7: B/(W) | F7: Actual | G7: YoY % | I7: Actual | J7: Budget | K7: B/(W) | M7: Actual | N7: YoY %
B8: Q1 2026 | C8: Q1 2026 | D8: Q1 2026 | F8: Q1 2025 | G8: 26 vs 25 | I8: YTD 2026 | J8: YTD 2026 | K8: YTD 2026 | M8: YTD 2025 | N8: 26 vs 25
A9: Beginning ARR | B9: 25000 | C9: 25000 | D9: =B9-C9 -> 0 | F9: 19077 | G9: =IFERROR((B9-F9)/ABS(F9),"-") -> 0.31047859 | I9: 25000 | J9: 25000 | K9: =I9-J9 -> 0 | M9: 19077 | N9: =IFERROR((I9-M9)/ABS(M9),"-") -> 0.31047859
A10: + New ARR | B10: 4627.31 | C10: 6770.4 | D10: =B10-C10 -> -2143.09 | F10: 1541.91 | G10: =IFERROR((B10-F10)/ABS(F10),"-") -> 2.0010247 | I10: 4627.31 | J10: 6770.4 | K10: =I10-J10 -> -2143.09 | M10: 1541.91 | N10: =IFERROR((I10-M10)/ABS(M10),"-") -> 2.0010247
A11: + Expansion ARR | B11: 477.84 | C11: 574 | D11: =B11-C11 -> -96.16 | F11: 353.05 | G11: =IFERROR((B11-F11)/ABS(F11),"-") -> 0.35346268 | I11: 477.84 | J11: 574 | K11: =I11-J11 -> -96.16 | M11: 353.05 | N11: =IFERROR((I11-M11)/ABS(M11),"-") -> 0.35346268
A12: − Downsell ARR | B12: -134.84 | C12: -114.8 | D12: =C12-B12 -> 20.04 | F12: -94.58 | G12: =IFERROR((B12-F12)/ABS(F12),"-") -> -0.42567139 | I12: -134.84 | J12: -114.8 | K12: =J12-I12 -> 20.04 | M12: -94.58 | N12: =IFERROR((I12-M12)/ABS(M12),"-") -> -0.42567139
A13: − Gross Churn ARR | B13: -330.31 | C13: -229.6 | D13: =C13-B13 -> 100.71 | F13: -189.38 | G13: =IFERROR((B13-F13)/ABS(F13),"-") -> -0.74416517 | I13: -330.31 | J13: -229.6 | K13: =J13-I13 -> 100.71 | M13: -189.38 | N13: =IFERROR((I13-M13)/ABS(M13),"-") -> -0.74416517
A14: Net New ARR | B14: =B10+B11+B12+B13 -> 4640 | C14: =C10+C11+C12+C13 -> 7000 | D14: =B14-C14 -> -2360 | F14: =F10+F11+F12+F13 -> 1611 | G14: =IFERROR((B14-F14)/ABS(F14),"-") -> 1.8801986 | I14: =I10+I11+I12+I13 -> 4640 | J14: =J10+J11+J12+J13 -> 7000 | K14: =I14-J14 -> -2360 | M14: =M10+M11+M12+M13 -> 1611 | N14: =IFERROR((I14-M14)/ABS(M14),"-") -> 1.8801986
A15: Ending ARR | B15: =B9+B10+B11+B12+B13 -> 29640 | C15: =C9+C10+C11+C12+C13 -> 32000 | D15: =B15-C15 -> -2360 | F15: =F9+F10+F11+F12+F13 -> 20688 | G15: =IFERROR((B15-F15)/ABS(F15),"-") -> 0.43271462 | I15: =I9+I10+I11+I12+I13 -> 29640 | J15: =J9+J10+J11+J12+J13 -> 32000 | K15: =I15-J15 -> -2360 | M15: =M9+M10+M11+M12+M13 -> 20688 | N15: =IFERROR((I15-M15)/ABS(M15),"-") -> 0.43271462
A18: SAAS KPIS
A19: ARR Churn Rate | B19: 0.018606 | C19: 0.013776 | D19: =IFERROR((B19-C19)*10000*-1,0) -> -48.3 | F19: 0.014885 | G19: =IFERROR((B19-F19)*10000*-1,0) -> -37.21 | I19: 0.018606 | J19: 0.013776 | K19: =IFERROR((I19-J19)*10000*-1,0) -> -48.3 | M19: 0.014885 | N19: =IFERROR((I19-M19)*10000*-1,0) -> -37.21
A20: Expansion Rate | B20: 0.019114 | C20: 0.02296 | D20: =IFERROR((B20-C20)*10000*1,0) -> -38.46 | F20: 0.018507 | G20: =IFERROR((B20-F20)*10000*1,0) -> 6.07 | I20: 0.019114 | J20: 0.02296 | K20: =IFERROR((I20-J20)*10000*1,0) -> -38.46 | M20: 0.018507 | N20: =IFERROR((I20-M20)*10000*1,0) -> 6.07
A21: Gross Revenue Retention (GRR) | B21: 0.981394 | C21: 0.986224 | D21: =IFERROR((B21-C21)*10000*1,0) -> -48.3 | F21: 0.985115 | G21: =IFERROR((B21-F21)*10000*1,0) -> -37.21 | I21: 0.981394 | J21: 0.986224 | K21: =IFERROR((I21-J21)*10000*1,0) -> -48.3 | M21: 0.985115 | N21: =IFERROR((I21-M21)*10000*1,0) -> -37.21
A22: Net Revenue Retention (NRR) | B22: 1.000507 | C22: 1.009184 | D22: =IFERROR((B22-C22)*10000*1,0) -> -86.77 | F22: 1.003622 | G22: =IFERROR((B22-F22)*10000*1,0) -> -31.15 | I22: 1.000507 | J22: 1.009184 | K22: =IFERROR((I22-J22)*10000*1,0) -> -86.77 | M22: 1.003622 | N22: =IFERROR((I22-M22)*10000*1,0) -> -31.15
A23: Net New ARR as % of Beg ARR | B23: =IFERROR(B14/B9,0) -> 0.1856 | C23: =IFERROR(C14/C9,0) -> 0.28 | D23: =IFERROR((B23-C23)*10000,0) -> -944 | F23: =IFERROR(F14/F9,0) -> 0.08444724 | G23: =IFERROR((B23-F23)*10000,0) -> 1011.5276 | I23: =IFERROR(I14/I9,0) -> 0.1856 | J23: =IFERROR(J14/J9,0) -> 0.28 | K23: =IFERROR((I23-J23)*10000,0) -> -944 | M23: =IFERROR(M14/M9,0) -> 0.08444724 | N23: =IFERROR((I23-M23)*10000,0) -> 1011.5276
A25: COMMENTARY
A26: — Ending ARR $29.6M, ~$2.4M below budget — new ARR bookings lag plan while the Q1 AE cohort ramps to full productivity.
A27: — New ARR $4.6M, below the $6.8M budget — reps are hired and onboarded on schedule; output is the lagging variable, not headcount.
A28: — Expansion ARR roughly in line with plan — existing-customer upsell motion unaffected by the new-hire ramp.
A29: — GRR below budget — CS capacity stretched during the hiring ramp; new CSM hires now onboarding to rebuild coverage.
A30: — NRR below budget for the same reason; expect normalization as new CS hires reach full capacity in Q2.
A32: All figures in $000s · Actuals through March 2026 · Budget = approved FY2026 plan

Sheet Natural Expense
A2: P&L by Month — Natural View
A3: Monthly natural P&L · Jan 2025 actuals through Dec 2026 forecast · All figures in $000s · Populated by Setpoint each cycle
C5: ← 2025 Actuals | O5: 2026 Actuals → | R5: ← 2026 Forecast
A6: ($000s) | C6: Jan-25 | D6: Feb-25 | E6: Mar-25 | F6: Apr-25 | G6: May-25 | H6: Jun-25 | I6: Jul-25 | J6: Aug-25 | K6: Sep-25 | L6: Oct-25 | M6: Nov-25 | N6: Dec-25 | O6: Jan-26 | P6: Feb-26 | Q6: Mar-26 | R6: Apr-26 | S6: May-26 | T6: Jun-26 | U6: Jul-26 | V6: Aug-26 | W6: Sep-26 | X6: Oct-26 | Y6: Nov-26 | Z6: Dec-26
A7: Revenue | C7: 1641.7 | D7: 1687.8 | E7: 1733.1 | F7: 1775.6 | G7: 1815.8 | H7: 1857 | I7: 1897.1 | J7: 1938.7 | K7: 1978.8 | L7: 2020 | M7: 2060.2 | N7: 2100.3 | O7: 2185.4 | P7: 2315.8 | Q7: 2445.6 | R7: 2609.64 | S7: 2823.12 | T7: 3037.04 | U7: 3251.38 | V7: 3466.15 | W7: 3681.35 | X7: 3896.98 | Y7: 4113.04 | Z7: 4329.53
A9: Salaries | C9: 872.5 | D9: 920 | E9: 929.6 | F9: 929.6 | G9: 929.6 | H9: 973.3 | I9: 973.3 | J9: 1031.8 | K9: 1031.8 | L9: 1075.6 | M9: 1075.6 | N9: 1075.6 | O9: 1090.2 | P9: 1123.1 | Q9: 1137.7 | R9: 1577 | S9: 1718.39 | T9: 1797.32 | U9: 1833.52 | V9: 1974.21 | W9: 2032.54 | X9: 2079.52 | Y9: 2150.31 | Z9: 2188.23
A10: Bonus / Commissions | C10: 82.7 | D10: 84.4 | E10: 85 | F10: 80.1 | G10: 80.3 | H10: 81.9 | I10: 82.2 | J10: 84.2 | K10: 84.5 | L10: 86 | M10: 86.3 | N10: 86.6 | O10: 184.2 | P10: 186.8 | Q10: 189 | R10: 258.46 | S10: 285.65 | T10: 300.72 | U10: 304.5 | V10: 332.4 | W10: 348.77 | X10: 357.75 | Y10: 363.53 | Z10: 367.47
A11: Benefits & Payroll Taxes | C11: 305.7 | D11: 321.4 | E11: 324.7 | F11: 323.1 | G11: 323.2 | H11: 337.7 | I11: 337.8 | J11: 357.1 | K11: 357.2 | L11: 371.7 | M11: 371.8 | N11: 371.9 | O11: 407.8 | P11: 419.2 | Q11: 424.6 | R11: 662.34 | S11: 721.73 | T11: 754.87 | U11: 770.08 | V11: 829.17 | W11: 853.67 | X11: 873.4 | Y11: 903.13 | Z11: 919.06
A12: Personnel Costs | C12: =SUM(C9:C11) -> 1260.9 | D12: =SUM(D9:D11) -> 1325.8 | E12: =SUM(E9:E11) -> 1339.3 | F12: =SUM(F9:F11) -> 1332.8 | G12: =SUM(G9:G11) -> 1333.1 | H12: =SUM(H9:H11) -> 1392.9 | I12: =SUM(I9:I11) -> 1393.3 | J12: =SUM(J9:J11) -> 1473.1 | ... Z12: =SUM(Z9:Z11) -> 3474.76
A14: Hosting | C14: 14.7 | D14: 15.1 | E14: 15.5 | F14: 15.9 | G14: 16.3 | H14: 16.6 | I14: 17 | J14: 17.4 | K14: 17.7 | L14: 18.1 | M14: 18.4 | N14: 18.8 | O14: 19.6 | P14: 20.7 | Q14: 21.9 | R14: 23.49 | S14: 25.41 | T14: 27.33 | U14: 29.26 | V14: 31.2 | W14: 33.13 | X14: 35.07 | Y14: 37.02 | Z14: 38.97
A15: Payment Processing | C15: 24.5 | D15: 25.2 | E15: 25.9 | F15: 26.5 | G15: 27.1 | H15: 27.7 | I15: 28.3 | J15: 28.9 | K15: 29.5 | L15: 30.2 | M15: 30.8 | N15: 31.3 | O15: 32.6 | P15: 34.6 | Q15: 36.5 | R15: 39.14 | S15: 42.35 | T15: 45.56 | U15: 48.77 | V15: 51.99 | W15: 55.22 | X15: 58.45 | Y15: 61.7 | Z15: 64.94
A16: Software & SaaS | C16: 61.6 | D16: 64.8 | E16: 65.6 | F16: 65.6 | G16: 65.6 | H16: 68.8 | I16: 68.8 | J16: 72.8 | K16: 72.8 | L16: 76 | M16: 76 | N16: 76 | O16: 76.8 | P16: 79.2 | Q16: 80 | R16: 88 | S16: 96 | T16: 100.8 | U16: 103.2 | V16: 110.4 | W16: 112.8 | X16: 115.2 | Y16: 120 | Z16: 122.4
A17: Travel & Entertainment | C17: 19.2 | D17: 20.2 | E17: 20.5 | F17: 20.5 | G17: 20.5 | H17: 21.5 | I17: 21.5 | J17: 22.7 | K17: 22.7 | L17: 23.7 | M17: 23.7 | N17: 23.7 | O17: 24 | P17: 24.7 | Q17: 25 | R17: 27.5 | S17: 30 | T17: 31.5 | U17: 32.25 | V17: 34.5 | W17: 35.25 | X17: 36 | Y17: 37.5 | Z17: 38.25
A18: Marketing Programs | C18: 49 | D18: 50.4 | E18: 51.7 | F18: 53 | G18: 54.2 | H18: 55.4 | I18: 56.6 | J18: 57.9 | K18: 59.1 | L18: 60.3 | M18: 61.5 | N18: 62.7 | O18: 65.2 | P18: 69.1 | Q18: 73 | R18: 78.29 | S18: 84.69 | T18: 91.11 | U18: 97.54 | V18: 103.98 | W18: 110.44 | X18: 116.91 | Y18: 123.39 | Z18: 129.89
A19: Professional Services | C19: 34.8 | D19: 35.4 | E19: 26.4 | F19: 23.4 | G19: 23.4 | H19: 35.6 | I19: 23.6 | J19: 38.8 | K19: 23.8 | L19: 36 | M19: 24 | N19: 24 | O19: 27 | P19: 33.2 | Q19: 27.2 | R19: 20 | S19: 20 | T19: 20 | U19: 20 | V19: 20 | W19: 20 | X19: 20 | Y19: 20 | Z19: 20
A20: Facilities | C20: 1.3 | D20: 1.4 | E20: 1.4 | F20: 1.4 | G20: 1.4 | H20: 1.5 | I20: 1.5 | J20: 1.5 | K20: 1.5 | L20: 1.6 | M20: 1.6 | N20: 1.6 | O20: 1.6 | P20: 1.7 | Q20: 1.7 | R20: 8 | S20: 8 | T20: 8 | U20: 8 | V20: 8 | W20: 8 | X20: 8 | Y20: 8 | Z20: 8
A21: Stock-Based Compensation (memo — non-cash, excluded from Total Operating Costs) | C21: 95.5 | D21: 100.4 | E21: 101.5 | F21: 101 | G21: 101 | H21: 105.5 | I21: 105.6 | J21: 111.6 | K21: 111.6 | L21: 116.2 | M21: 116.2 | N21: 116.2 | O21: 127.4 | P21: 131 | Q21: 132.7 | R21: 157.7 | S21: 171.84 | T21: 179.73 | U21: 183.35 | V21: 197.42 | W21: 203.25 | X21: 207.95 | Y21: 215.03 | Z21: 218.82
A22: Depreciation & Amortization (memo — non-operating, excluded from Total Operating Costs) | C22: 15 | D22: 15 | E22: 15 | F22: 15 | G22: 15 | H22: 15 | I22: 15 | J22: 15 | K22: 15 | L22: 15 | M22: 15 | N22: 15 | O22: 15 | P22: 15 | Q22: 15 | R22: 5 | S22: 5 | T22: 5 | U22: 5 | V22: 5 | W22: 5 | X22: 5 | Y22: 5 | Z22: 5
A23: Total Operating Costs | C23: =C12+SUM(C14:C20) -> 1466 | D23: =D12+SUM(D14:D20) -> 1538.3 | E23: =E12+SUM(E14:E20) -> 1546.3 | F23: =F12+SUM(F14:F20) -> 1539.1 | G23: =G12+SUM(G14:G20) -> 1541.6 | H23: =H12+SUM(H14:H20) -> 1620 | I23: =I12+SUM(I14:I20) -> 1610.6 | J23: =J12+SUM(J14:J20) -> 1713.1 | ... Z23: =Z12+SUM(Z14:Z20) -> 3897.21
A25: EBITDA | C25: =C7-C23 -> 175.7 | D25: =D7-D23 -> 149.5 | E25: =E7-E23 -> 186.8 | F25: =F7-F23 -> 236.5 | G25: =G7-G23 -> 274.2 | H25: =H7-H23 -> 237 | I25: =I7-I23 -> 286.5 | J25: =J7-J23 -> 225.6 | ... Z25: =Z7-Z23 -> 432.32
A26: EBITDA Margin % | C26: =C25/C7 -> 0.10702321 | D26: =D25/D7 -> 0.088576846 | E26: =E25/E7 -> 0.10778374 | F26: =F25/F7 -> 0.13319441 | G26: =G25/G7 -> 0.15100782 | H26: =H25/H7 -> 0.1276252 | I26: =I25/I7 -> 0.15101998 | J26: =J25/J7 -> 0.11636664 | ... Z26: =Z25/Z7 -> 0.099853795

Sheet P&L Monthly
A2: P&L by Month — Functional View
A3: Monthly functional P&L · Jan 2025 through Dec 2026 · All figures in $000s · Populated by Setpoint each cycle
C5: ← 2025 (Prior Year) | O5: 2026 (Current Year) →
A6: ($000s) | C6: Jan-25 | D6: Feb-25 | E6: Mar-25 | F6: Apr-25 | G6: May-25 | H6: Jun-25 | I6: Jul-25 | J6: Aug-25 | K6: Sep-25 | L6: Oct-25 | M6: Nov-25 | N6: Dec-25 | O6: Jan-26 | P6: Feb-26 | Q6: Mar-26 | R6: Apr-26 | S6: May-26 | T6: Jun-26 | U6: Jul-26 | V6: Aug-26 | W6: Sep-26 | X6: Oct-26 | Y6: Nov-26 | Z6: Dec-26
A7: Revenue | C7: 1641.7 | D7: 1687.8 | E7: 1733.1 | F7: 1775.6 | G7: 1815.8 | H7: 1857 | I7: 1897.1 | J7: 1938.7 | K7: 1978.8 | L7: 2020 | M7: 2060.2 | N7: 2100.3 | O7: 2185.4 | P7: 2315.8 | Q7: 2445.6 | R7: 2609.6 | S7: 2823.1 | T7: 3037 | U7: 3251.4 | V7: 3466.1 | W7: 3681.3 | X7: 3897 | Y7: 4113 | Z7: 4329.5
A9: COGS | C9: 333.1 | D9: 349.5 | E9: 361.6 | F9: 371.8 | G9: 377.2 | H9: 385.1 | I9: 394.5 | J9: 443 | K9: 450.8 | L9: 483.6 | M9: 502.4 | N9: 499.6 | O9: 378.5 | P9: 412.2 | Q9: 415.3 | R9: 568.2 | S9: 612.3 | T9: 635.8 | U9: 641 | V9: 695.2 | W9: 700.3 | X9: 705.5 | Y9: 746 | Z9: 751.2
A10: Gross Profit | C10: =C7-C9 -> 1308.6 | D10: =D7-D9 -> 1338.3 | E10: =E7-E9 -> 1371.5 | F10: =F7-F9 -> 1403.8 | G10: =G7-G9 -> 1438.6 | H10: =H7-H9 -> 1471.9 | I10: =I7-I9 -> 1502.6 | J10: =J7-J9 -> 1495.7 | ... Z10: =Z7-Z9 -> 3578.3
A11: Gross Margin % | C11: =C10/C7 -> 0.79710057 | D11: =D10/D7 -> 0.7929257 | E11: =E10/E7 -> 0.79135653 | F11: =F10/F7 -> 0.79060599 | G11: =G10/G7 -> 0.79226787 | H11: =H10/H7 -> 0.79262251 | I11: =I10/I7 -> 0.79205103 | J11: =J10/J7 -> 0.77149636 | ... Z11: =Z10/Z7 -> 0.82649267
A13: R&D | C13: 369.5 | D13: 383.5 | E13: 395.4 | F13: 414.8 | G13: 424.1 | H13: 431.6 | I13: 463.8 | J13: 461.5 | K13: 466.8 | L13: 488.7 | M13: 504.7 | N13: 508.1 | O13: 570.4 | P13: 572.8 | Q13: 593.5 | R13: 667.7 | S13: 710.7 | T13: 748.9 | U13: 773.1 | V13: 820.6 | W13: 843.9 | X13: 865.6 | Y13: 894.7 | Z13: 919.4
A14: S&M | C14: 403.4 | D14: 403.4 | E14: 419 | F14: 431.8 | G14: 453.1 | H14: 476.6 | I14: 513.8 | J14: 500.5 | K14: 522.1 | L14: 542.6 | M14: 568 | N14: 606.2 | O14: 740.7 | P14: 777.5 | Q14: 783.9 | R14: 1338.9 | S14: 1492.8 | T14: 1576.1 | U14: 1616.7 | V14: 1750.5 | W14: 1836.1 | X14: 1899.7 | Y14: 1945 | Z14: 1987.8
A15: G&A | C15: 170.2 | D15: 175.6 | E15: 180.2 | F15: 178.4 | G15: 180.5 | H15: 186.2 | I15: 192.2 | J15: 187.5 | K15: 209.5 | L15: 208.2 | M15: 201 | N15: 219.6 | O15: 239.4 | P15: 229.7 | Q15: 223.8 | R15: 207.4 | S15: 216.4 | T15: 216.4 | U15: 216.4 | V15: 229.5 | W15: 229.5 | X15: 229.5 | Y15: 238.9 | Z15: 238.9
A16: Total OpEx | C16: =SUM(C13:C15) -> 943.1 | D16: =SUM(D13:D15) -> 962.5 | E16: =SUM(E13:E15) -> 994.6 | F16: =SUM(F13:F15) -> 1025 | G16: =SUM(G13:G15) -> 1057.7 | H16: =SUM(H13:H15) -> 1094.4 | I16: =SUM(I13:I15) -> 1169.8 | J16: =SUM(J13:J15) -> 1149.5 | ... Z16: =SUM(Z13:Z15) -> 3146.1
A18: EBITDA | C18: =C10-C16 -> 365.5 | D18: =D10-D16 -> 375.8 | E18: =E10-E16 -> 376.9 | F18: =F10-F16 -> 378.8 | G18: =G10-G16 -> 380.9 | H18: =H10-H16 -> 377.5 | I18: =I10-I16 -> 332.8 | J18: =J10-J16 -> 346.2 | ... Z18: =Z10-Z16 -> 432.2
A19: EBITDA Margin % | C19: =C18/C7 -> 0.22263507 | D19: =D18/D7 -> 0.22265671 | E19: =E18/E7 -> 0.21747158 | F19: =F18/F7 -> 0.21333634 | G19: =G18/G7 -> 0.2097698 | H19: =H18/H7 -> 0.20328487 | I19: =I18/I7 -> 0.17542565 | J19: =J18/J7 -> 0.17857327 | ... Z19: =Z18/Z7 -> 0.09982677
A22: Headcount by Function
A23: COGS (CS, Professional Svcs, Infra) | C23: 21 | D23: 22 | E23: 22 | F23: 22 | G23: 22 | H23: 22 | I23: 22 | J23: 24 | K23: 24 | L23: 24 | M23: 24 | N23: 24 | O23: 24 | P23: 26 | Q23: 26 | R23: 27 | S23: 29 | T23: 30 | U23: 30 | V23: 32 | W23: 32 | X23: 32 | Y23: 34 | Z23: 34
A24: R&D (Engineering, Data Science) | C24: 20 | D24: 21 | E24: 21 | F24: 21 | G24: 21 | H24: 22 | I24: 22 | J24: 23 | K24: 23 | L24: 24 | M24: 24 | N24: 24 | O24: 25 | P24: 25 | Q24: 26 | R24: 28 | S24: 30 | T24: 32 | U24: 33 | V24: 35 | W24: 36 | X24: 37 | Y24: 38 | Z24: 39
A25: S&M (Sales, Marketing) | C25: 25 | D25: 26 | E25: 27 | F25: 27 | G25: 27 | H25: 30 | I25: 30 | J25: 30 | K25: 30 | L25: 33 | M25: 33 | N25: 33 | O25: 33 | P25: 35 | Q25: 35 | R25: 41 | S25: 46 | T25: 49 | U25: 51 | V25: 55 | W25: 57 | X25: 59 | Y25: 61 | Z25: 63
A26: G&A (Finance, People Ops) | C26: 11 | D26: 12 | E26: 12 | F26: 12 | G26: 12 | H26: 12 | I26: 12 | J26: 14 | K26: 14 | L26: 14 | M26: 14 | N26: 14 | O26: 14 | P26: 14 | Q26: 14 | R26: 14 | S26: 15 | T26: 15 | U26: 15 | V26: 16 | W26: 16 | X26: 16 | Y26: 17 | Z26: 17
A27: Total Headcount | C27: =SUM(C23:C26) -> 77 | D27: =SUM(D23:D26) -> 81 | E27: =SUM(E23:E26) -> 82 | F27: =SUM(F23:F26) -> 82 | G27: =SUM(G23:G26) -> 82 | H27: =SUM(H23:H26) -> 86 | I27: =SUM(I23:I26) -> 86 | J27: =SUM(J23:J26) -> 91 | ... Z27: =SUM(Z23:Z26) -> 153

Sheet ARR Monthly
A2: ARR Rollforward & SaaS KPIs by Month
A3: Monthly ARR bridge and key SaaS metrics · Jan 2025 (actuals) through Dec 2026 (forecast) · All ARR figures in $000s · Populated by Setpoint each cycle
C5: ← 2025 Actuals (Prior Year) | O5: 2026 Actuals → | R5: ← 2026 Forecast
A6: ($000s) | C6: Jan-25 | D6: Feb-25 | E6: Mar-25 | F6: Apr-25 | G6: May-25 | H6: Jun-25 | I6: Jul-25 | J6: Aug-25 | K6: Sep-25 | L6: Oct-25 | M6: Nov-25 | N6: Dec-25 | O6: Jan-26 | P6: Feb-26 | Q6: Mar-26 | R6: Apr-26 | S6: May-26 | T6: Jun-26 | U6: Jul-26 | V6: Aug-26 | W6: Sep-26 | X6: Oct-26 | Y6: Nov-26 | Z6: Dec-26
A7: ARR ROLLFORWARD
A8: Beginning ARR | C8: 19077 | D8: 19614 | E8: 20151 | F8: 20688 | G8: 21167 | H8: 21646 | I8: 22125 | J8: 22604 | K8: 23084 | L8: 23563 | M8: 24042 | N8: 24521 | O8: 25000 | P8: 26547 | Q8: 28093 | R8: 29640 | S8: 32199.3 | T8: 34763.7 | U8: 37333.2 | V8: 39907.9 | W8: 42487.7 | X8: 45072.7 | Y8: 47662.8 | Z8: 50258.1
A10: + New ARR | C10: 514 | D10: 514 | E10: 514 | F10: 456 | G10: 456 | H10: 456 | I10: 456 | J10: 456 | K10: 456 | L10: 456 | M10: 456 | N10: 457 | O10: 1533 | P10: 1542 | Q10: 1552 | R10: 2500 | S10: 2500 | T10: 2500 | U10: 2500 | V10: 2500 | W10: 2500 | X10: 2500 | Y10: 2500 | Z10: 2500
A11: + Expansion ARR | C11: 114 | D11: 118 | E11: 121 | F11: 124 | G11: 127 | H11: 130 | I11: 133 | J11: 136 | K11: 139 | L11: 141 | M11: 144 | N11: 147 | O11: 150 | P11: 159 | Q11: 169 | R11: 207.5 | S11: 225.4 | T11: 243.3 | U11: 261.3 | V11: 279.4 | W11: 297.4 | X11: 315.5 | Y11: 333.6 | Z11: 351.8
A12: − Downsell ARR | C12: -31 | D12: -32 | E12: -33 | F12: -34 | G12: -34 | H12: -35 | I12: -36 | J12: -37 | K12: -38 | L12: -39 | M12: -40 | N12: -41 | O12: -42 | P12: -45 | Q12: -48 | R12: -44.5 | S12: -48.3 | T12: -52.1 | U12: -56 | V12: -59.9 | W12: -63.7 | X12: -67.6 | Y12: -71.5 | Z12: -75.4
A13: − Gross Churn ARR | C13: -61 | D13: -63 | E13: -65 | F13: -67 | G13: -69 | H13: -71 | I13: -73 | J13: -75 | K13: -77 | L13: -79 | M13: -81 | N13: -83 | O13: -94 | P13: -110 | Q13: -126 | R13: -103.7 | S13: -112.7 | T13: -121.7 | U13: -130.7 | V13: -139.7 | W13: -148.7 | X13: -157.8 | Y13: -166.8 | Z13: -175.9
A15: Net New ARR | C15: =SUM(C10:C13) -> 536 | D15: =SUM(D10:D13) -> 537 | E15: =SUM(E10:E13) -> 537 | F15: =SUM(F10:F13) -> 479 | G15: =SUM(G10:G13) -> 480 | H15: =SUM(H10:H13) -> 480 | I15: =SUM(I10:I13) -> 480 | J15: =SUM(J10:J13) -> 480 | ... Z15: =SUM(Z10:Z13) -> 2600.5
A16: Ending ARR | C16: =C8+C15 -> 19613 | D16: =D8+D15 -> 20151 | E16: =E8+E15 -> 20688 | F16: =F8+F15 -> 21167 | G16: =G8+G15 -> 21647 | H16: =H8+H15 -> 22126 | I16: =I8+I15 -> 22605 | J16: =J8+J15 -> 23084 | ... Z16: =Z8+Z15 -> 52858.6
A18: SAAS KPIs
A19: Gross Revenue Retention (GRR) | C19: =(C8+C12+C13)/C8 -> 0.99517744 | D19: =(D8+D12+D13)/D8 -> 0.99515652 | E19: =(E8+E12+E13)/E8 -> 0.99513672 | F19: =(F8+F12+F13)/F8 -> 0.99511794 | G19: =(G8+G12+G13)/G8 -> 0.99513393 | H19: =(H8+H12+H13)/H8 -> 0.99510302 | I19: =(I8+I12+I13)/I8 -> 0.99507345 | J19: =(J8+J12+J13)/J8 -> 0.99504512 | ... Z19: =(Z8+Z12+Z13)/Z8 -> 0.99499981
A20: Net Revenue Retention (NRR) | C20: =(C8+C11+C12+C13)/C8 -> 1.0011532 | D20: =(D8+D11+D12+D13)/D8 -> 1.0011726 | E20: =(E8+E11+E12+E13)/E8 -> 1.0011414 | F20: =(F8+F11+F12+F13)/F8 -> 1.0011118 | G20: =(G8+G11+G12+G13)/G8 -> 1.0011338 | H20: =(H8+H11+H12+H13)/H8 -> 1.0011087 | I20: =(I8+I11+I12+I13)/I8 -> 1.0010847 | J20: =(J8+J11+J12+J13)/J8 -> 1.0010618 | ... Z20: =(Z8+Z11+Z12+Z13)/Z8 -> 1.0019997
A21: Net New ARR as % of Beginning ARR | C21: =C15/C8 -> 0.028096661 | D21: =D15/D8 -> 0.027378403 | E21: =E15/E8 -> 0.026648802 | F21: =F15/F8 -> 0.023153519 | G21: =G15/G8 -> 0.022676808 | H21: =H15/H8 -> 0.022174998 | I21: =I15/I8 -> 0.021694915 | J21: =J15/J8 -> 0.02123518 | ... Z21: =Z15/Z8 -> 0.051742903
A23: GRR = (Beg ARR + Downsell + Gross Churn) / Beg ARR · NRR = (Beg ARR + Expansion + Downsell + Gross Churn) / Beg ARR · Both calculated on beginning-of-period ARR

Sheet Forecast Inputs
B1: FORECAST INPUTS · CLIENT COMPLETES EACH CYCLE
B2: Confirm or revise the forward assumptions before the monthly review meeting.
B3: Q1 2026 cycle · Prepared by Setpoint Finance · Return completed before the review meeting
B4: Your columns are E, F, and G — highlighted in blue. Column C shows trailing actuals for context. Column D shows the current forecast assumption.
A6: DATA INPUTS · Complete once per cycle before sharing
A7: # | B7: Item | C7: Trailing actuals (context) | D7: Current assumption | E7: Confirm / Revise | F7: Updated value | G7: Notes
A8: ↵ | B8: Cash balance Current cash and equivalents from latest bank statement | C8: Enter as of date: ___________ | D8: — | E8: 14200000 | G8: Used on Board Overview — cash tile and runway calculation
A10: SECTION 1 — MONTHLY INPUTS · Review and confirm or revise each cycle
A11: # | B11: Category · Assumption | C11: Trailing actuals (context) | D11: Current forecast assumption | E11: Confirm / Revise | F11: Updated value (if Revise) | G11: Notes / context
A12: 1 | B12: ARR — New bookings Monthly New ARR target ($) | C12: Q1 monthly avg: $1.54M | D12: $2,500,000 / month
A13: 2 | B13: ARR — Expansion Monthly expansion rate (% of Beg ARR) | C13: Q1 monthly avg: 0.60% of Beg ARR | D13: 0.70% of Beg ARR
A14: 3 | B14: ARR — Gross churn Monthly gross churn rate (% of Beg ARR) | C14: Q1 monthly avg: 0.41% of Beg ARR (elevated — CS capacity stretched) | D14: 0.35% of Beg ARR
A15: 4 | B15: ARR — Downsell / contraction Monthly downsell rate (% of Beg ARR) | C15: Q1 monthly avg: 0.17% of Beg ARR | D15: 0.15% of Beg ARR
A16: 5 | B16: ARR — Known deals / adjustments Specific deals or events not in base assumption | C16: None material in Q1 | D16: None currently identified
A17: 6 | B17: Sales — Quota attainment Assumed rep attainment rate | C17: Not yet at full ramp — Q1 cohort still onboarding | D17: 75%
A18: 7 | B18: Sales — Win rate Pipeline win rate assumption | C18: Q1 informal estimate: ~24% | D18: 27%
A19: 8 | B19: Headcount — AE hiring plan Quota-carrying rep starts (next 90 days) | C19: 19 → 25 reps since Jan-25 (+6 in Q1 2026) | D19: +7 reps planned (Apr–Jun) | G19: Translated into Company Roster "Planned" entries, not a direct model input
A20: 9 | B20: Headcount — All other Non-AE planned starts (next 90 days) | C20: 58 → 75 heads since Jan-25 (+8 in Q1 2026, ex-AE) | D20: +14 planned (Apr–Jun), concentrated in Eng & CS | G20: Translated into Company Roster "Planned" entries, not a direct model input
A21: 10 | B21: Cost — Marketing programs Marketing spend as % of revenue | C21: 3.0% of revenue | D21: 3.0% of revenue
A22: 11 | B22: Cost — Payment processing Payment processing as % of revenue | C22: 1.5% of revenue | D22: 1.5% of revenue
A23: 12 | B23: Revenue — Professional services Monthly PS revenue ($) | C23: Q1 monthly avg: $27.5K | D23: $33,000 / month
A24: 13 | B24: Cost — Hosting & infrastructure Hosting/cloud cost as % of revenue | C24: Q1 average: 0.9% of revenue | D24: 0.9% of revenue
A25: 14 | B25: Cost — Facilities Fixed monthly office/facilities cost ($) | C25: Q1 average: ~$1,670 / month | D25: $8,000 / month — reflects planned office footprint expansion past 100 heads
A27: SECTION 2 — STANDING ASSUMPTIONS · Quarterly review — flag changes only
A28: # | B28: Category · Assumption | C28: Current value | D28: Basis / source | E28: Flag change? | F28: Updated value | G28: Notes
A29: S1 | B29: Quota per rep Annual quota per quota-carrying AE | C29: $1,000,000 / rep / year | D29: Sales plan — approved FY2026 | E29: No change
